WARNING:root:PID file was found but process with its PID not running. Removing PID file
INFO:root:BASE CONNECTED
INFO:root:*** BOT was started. PID=43485
INFO:aiogram:Bot: AdBot [@adreallynotabot_bot]
ERROR:asyncio:Task exception was never retrieved
future: <Task finished name='Task-4' coro=<sync_func() done, defined at /home/proger/adbot/source/base/googledocs.py:133> exception=KeyboardInterrupt()>
Traceback (most recent call last):
  File "/home/proger/adbot/source/parser.py", line 139, in parse_campaigns
    for item in response['response']:
KeyError: 'response'

During handling of the above exception, another exception occurred:

Traceback (most recent call last):
  File "/home/proger/.local/lib/python3.10/site-packages/aiogram/utils/executor.py", line 320, in start_polling
    loop.run_until_complete(self._startup_polling())
  File "/usr/lib/python3.10/asyncio/base_events.py", line 633, in run_until_complete
    self.run_forever()
  File "/usr/lib/python3.10/asyncio/base_events.py", line 600, in run_forever
    self._run_once()
  File "/usr/lib/python3.10/asyncio/base_events.py", line 1896, in _run_once
    handle._run()
  File "/usr/lib/python3.10/asyncio/events.py", line 80, in _run
    self._context.run(self._callback, *self._args)
  File "/home/proger/adbot/source/base/googledocs.py", line 144, in sync_func
    await full_sync_with_docs()
  File "/home/proger/adbot/source/base/googledocs.py", line 128, in full_sync_with_docs
    await fill_page(account, client, current_page, new)
  File "/home/proger/adbot/source/base/googledocs.py", line 99, in fill_page
    result = await parse_campaigns(account, client['id'], last)
  File "/home/proger/adbot/source/parser.py", line 146, in parse_campaigns
    sleep(10)
KeyboardInterrupt
WARNING:root:PID file was found but process with its PID not running. Removing PID file
INFO:root:BASE CONNECTED
INFO:root:*** BOT was started. PID=43495
INFO:aiogram:Bot: AdBot [@adreallynotabot_bot]
INFO:aiogram.dispatcher.dispatcher:Start polling.
ERROR:aiogram.dispatcher.dispatcher:Cause exception while getting updates.
Traceback (most recent call last):
  File "/home/proger/.local/lib/python3.10/site-packages/aiogram/dispatcher/dispatcher.py", line 381, in start_polling
    updates = await self.bot.get_updates(
  File "/home/proger/.local/lib/python3.10/site-packages/aiogram/bot/bot.py", line 110, in get_updates
    result = await self.request(api.Methods.GET_UPDATES, payload)
  File "/home/proger/.local/lib/python3.10/site-packages/aiogram/bot/base.py", line 231, in request
    return await api.make_request(await self.get_session(), self.server, self.__token, method, data, files,
  File "/home/proger/.local/lib/python3.10/site-packages/aiogram/bot/api.py", line 140, in make_request
    return check_result(method, response.content_type, response.status, await response.text())
  File "/home/proger/.local/lib/python3.10/site-packages/aiogram/bot/api.py", line 119, in check_result
    exceptions.ConflictError.detect(description)
  File "/home/proger/.local/lib/python3.10/site-packages/aiogram/utils/exceptions.py", line 140, in detect
    raise err(cls.text or description)
aiogram.utils.exceptions.TerminatedByOtherGetUpdates: Terminated by other getupdates request; make sure that only one bot instance is running
INFO:root:OK: SELECT is_admin FROM users WHERE id = %s
ERROR:asyncio:Task exception was never retrieved
future: <Task finished name='Task-14' coro=<Dispatcher._process_polling_updates() done, defined at /home/proger/.local/lib/python3.10/site-packages/aiogram/dispatcher/dispatcher.py:407> exception=MessageNotModified('Message is not modified: specified new message content and reply markup are exactly the same as a current content and reply markup of the message')>
Traceback (most recent call last):
  File "/home/proger/.local/lib/python3.10/site-packages/aiogram/dispatcher/dispatcher.py", line 415, in _process_polling_updates
    for responses in itertools.chain.from_iterable(await self.process_updates(updates, fast)):
  File "/home/proger/.local/lib/python3.10/site-packages/aiogram/dispatcher/dispatcher.py", line 235, in process_updates
    return await asyncio.gather(*tasks)
  File "/home/proger/.local/lib/python3.10/site-packages/aiogram/dispatcher/handler.py", line 116, in notify
    response = await handler_obj.handler(*args, **partial_data)
  File "/home/proger/.local/lib/python3.10/site-packages/aiogram/dispatcher/dispatcher.py", line 283, in process_update
    return await self.callback_query_handlers.notify(update.callback_query)
  File "/home/proger/.local/lib/python3.10/site-packages/aiogram/dispatcher/handler.py", line 116, in notify
    response = await handler_obj.handler(*args, **partial_data)
  File "/home/proger/adbot/source/handler/commands.py", line 64, in new_button
    await event.message.edit_reply_markup(back_to_settings_button)
  File "/home/proger/.local/lib/python3.10/site-packages/aiogram/types/message.py", line 2925, in edit_reply_markup
    return await self.bot.edit_message_reply_markup(
  File "/home/proger/.local/lib/python3.10/site-packages/aiogram/bot/bot.py", line 2865, in edit_message_reply_markup
    result = await self.request(api.Methods.EDIT_MESSAGE_REPLY_MARKUP, payload)
  File "/home/proger/.local/lib/python3.10/site-packages/aiogram/bot/base.py", line 231, in request
    return await api.make_request(await self.get_session(), self.server, self.__token, method, data, files,
  File "/home/proger/.local/lib/python3.10/site-packages/aiogram/bot/api.py", line 140, in make_request
    return check_result(method, response.content_type, response.status, await response.text())
  File "/home/proger/.local/lib/python3.10/site-packages/aiogram/bot/api.py", line 115, in check_result
    exceptions.BadRequest.detect(description)
  File "/home/proger/.local/lib/python3.10/site-packages/aiogram/utils/exceptions.py", line 140, in detect
    raise err(cls.text or description)
aiogram.utils.exceptions.MessageNotModified: Message is not modified: specified new message content and reply markup are exactly the same as a current content and reply markup of the message
ERROR:aiogram.dispatcher.dispatcher:Cause exception while getting updates.
Traceback (most recent call last):
  File "/home/proger/.local/lib/python3.10/site-packages/aiogram/dispatcher/dispatcher.py", line 381, in start_polling
    updates = await self.bot.get_updates(
  File "/home/proger/.local/lib/python3.10/site-packages/aiogram/bot/bot.py", line 110, in get_updates
    result = await self.request(api.Methods.GET_UPDATES, payload)
  File "/home/proger/.local/lib/python3.10/site-packages/aiogram/bot/base.py", line 231, in request
    return await api.make_request(await self.get_session(), self.server, self.__token, method, data, files,
  File "/home/proger/.local/lib/python3.10/site-packages/aiogram/bot/api.py", line 140, in make_request
    return check_result(method, response.content_type, response.status, await response.text())
  File "/home/proger/.local/lib/python3.10/site-packages/aiogram/bot/api.py", line 119, in check_result
    exceptions.ConflictError.detect(description)
  File "/home/proger/.local/lib/python3.10/site-packages/aiogram/utils/exceptions.py", line 140, in detect
    raise err(cls.text or description)
aiogram.utils.exceptions.TerminatedByOtherGetUpdates: Terminated by other getupdates request; make sure that only one bot instance is running
INFO:aiogram.dispatcher.dispatcher:Stop polling...
WARNING:aiogram:Goodbye!
INFO:root:*** BOT was stopped. PID=43495
